Workbook

Sheet Shuvojit
A1: Website | B1: Home Page | D1: Collection Page | F1: Product Details Page | H1: Page Speed URLs
B2: Mobile | C2: Desktop | D2: Mobile | E2: Desktop | F2: Mobile | G2: Desktop | H2: Home Page | I2: Collection Page | J2: PDP
A3: https://edenmaystudio.co.uk | B3: ASKING FOR SIGNUP
A4: https://fashioneyewear.com | B4: 29 | C4: 38 | D4: 33 | E4: 44 | F4: 6 | G4: 53 | H4: https://pagespeed.web.dev/analysis/https-www-fashioneyewear-com-en-in/smmpv9gz53?form_factor=desktop | I4: https://pagespeed.web.dev/analysis/https-www-fashioneyewear-com-en-in-collections-all/2rgcyj22yo?form_factor=desktop | J4: https://pagespeed.web.dev/analysis/https-www-fashioneyewear-com-en-in-products-adidas-sp0063/awlwfcwwml?form_factor=mobile
A5: https://buttahlondon.com | B5: 34 | C5: 57 | D5: 49 | E5: 54 | F5: 48 | G5: 70 | H5: https://pagespeed.web.dev/analysis/https-buttahlondon-com/b0o780lgib?form_factor=desktop | I5: https://pagespeed.web.dev/analysis/https-buttahlondon-com-collections-all/fy3lhyzo4y?form_factor=desktop | J5: https://pagespeed.web.dev/analysis/https-buttahlondon-com-products-long-tank-top/jup1sr8f6v?form_factor=desktop
A6: https://ayamset.com | B6: 75 | C6: 85 | D6: 66 | E6: 88 | F6: 37 | G6: 55 | H6: https://pagespeed.web.dev/analysis/https-ayamset-com/ghd1mbubew?form_factor=mobile | I6: https://pagespeed.web.dev/analysis/https-ayamset-com-collections-all/dloiqcf0n0?form_factor=desktop | J6: https://pagespeed.web.dev/analysis/https-www-mytheresa-com-gb-en-women-marant-etoile-anasta-faux-fur-jacket-brown-p01003106/xv6fz84x69?form_factor=desktop
A7: https://ibizafashionfestival.com | B7: 75 | C7: 97 | D7: 89 | E7: 99 | F7: 78 | G7: 91 | H7: https://pagespeed.web.dev/analysis/https-ibizafashionfestival-com/e33cb5be8o?form_factor=desktop | I7: https://pagespeed.web.dev/analysis/https-ibizafashionfestival-com-collections-all/16y6eo6i3n?form_factor=desktop | J7: https://pagespeed.web.dev/analysis/https-ibizafashionfestival-com-products-cassandra-swimsuit-copy/znkm6poqc4?form_factor=desktop
A8: https://comhla.co.uk | B8: 58 | C8: 74 | D8: 60 | E8: 67 | F8: 60 | G8: 65 | H8: https://pagespeed.web.dev/analysis/https-comhla-co-uk/xj3mhzjg69?form_factor=mobile | I8: https://pagespeed.web.dev/analysis/https-comhla-co-uk-collections-women-Buy-Well/snijwz3gka?form_factor=desktop | J8: https://pagespeed.web.dev/analysis/https-comhla-co-uk-products-large-merino-triangle-scarf-in-red-stripe/erkz3kzv1y?form_factor=desktop
A9: https://abtany.com | B9: 69 | C9: 76 | D9: 78 | E9: 95 | F9: 72 | G9: 61 | H9: https://pagespeed.web.dev/analysis/https-www-abtany-com/cknuwkkg17?form_factor=desktop | I9: https://pagespeed.web.dev/analysis/https-www-abtany-com-collections-all/c6tj7iijfh?form_factor=desktop | J9: https://pagespeed.web.dev/analysis/https-www-abtany-com-products-black-drawstring-swim-shorts-copy/oota3tca4a?form_factor=desktop
A10: https://heidiklein.com | B10: 67 | C10: 85 | D10: 45 | E10: 55 | F10: 62 | G10: 82 | H10: https://pagespeed.web.dev/analysis/https-heidiklein-com/y52ob8p4bk?form_factor=desktop | I10: https://pagespeed.web.dev/analysis/https-heidiklein-com-collections-all/p1u9jza6ae?form_factor=desktop | J10: https://pagespeed.web.dev/analysis/https-heidiklein-com-products-at-lace-beach-shirt/wtdlriagb2?form_factor=desktop
A11: https://bbxbrand.com | B11: 21 | C11: 40 | D11: 38 | E11: 44 | F11: 42 | G11: 54 | H11: https://pagespeed.web.dev/analysis/https-www-bbxbrand-com/kf5ktzowl3?form_factor=desktop | I11: https://pagespeed.web.dev/analysis/https-www-bbxbrand-com-collections-all/wokjoidnfs?form_factor=desktop | J11: https://pagespeed.web.dev/analysis/https-www-bbxbrand-com-collections-all-products-waterfall-mini-lime-green/nf1bqiej49?form_factor=desktop
A12: https://amelry.com | B12: 68 | C12: 66 | D12: 65 | E12: 74 | F12: 60 | G12: 63 | H12: https://pagespeed.web.dev/analysis/https-amelry-com/4njxzoa9n9?form_factor=desktop | I12: https://pagespeed.web.dev/analysis/https-palaceofnowhere-co-uk-collections-all/9gxd3nwsm5?form_factor=mobile | J12: https://pagespeed.web.dev/analysis/https-amelry-com-products-beige-shirred-dress/0u2uq28kic?form_factor=desktop
A13: https://havvamustafa.com | B13: 58 | C13: 87 | D13: 71 | E13: 53 | F13: 61 | G13: 76 | H13: https://pagespeed.web.dev/analysis/https-havvamustafa-com/8g2oxt6b74?form_factor=desktop | I13: https://pagespeed.web.dev/analysis/https-havvamustafa-com-collections-all/m1s1qj7w18?form_factor=desktop | J13: https://pagespeed.web.dev/analysis/https-havvamustafa-com-collections-all-products-netto-texas-tall-black/dmuejrxh7w?form_factor=desktop
A14: https://farafieldclothing.com | B14: 52 | C14: 65 | D14: 51 | E14: 63 | F14: 43 | G14: 50 | H14: https://pagespeed.web.dev/analysis/https-farafieldclothing-com/lsp3w2q7io?form_factor=desktop | I14: https://pagespeed.web.dev/analysis/https-farafieldclothing-com/1nvi3bc49h?form_factor=desktop | J14: https://pagespeed.web.dev/analysis/https-farafieldclothing-com-products-aleksey-horace-zip-sand/kuxk4k7vqz?form_factor=desktop
A15: https://batchldn.com | B15: 54 | C15: 87 | D15: 41 | E15: 70 | F15: 43 | G15: 58 | H15: https://pagespeed.web.dev/analysis/https-batchldn-com/dzy2rllpke?form_factor=desktop | I15: https://pagespeed.web.dev/analysis/https-batchldn-com-collections-all/c63rnbo5o9?form_factor=desktop | J15: https://pagespeed.web.dev/analysis/https-batchldn-com-products-batch-silk-scarf-season-1-heads-by-rashad-al-karooni-scarlet/2ltdjhpcj7?form_factor=desktop
... A37: https://hydur.com | B37: 33 | C37: 38 | D37: 27 | E37: 51 | F37: 30 | G37: 40 | H37: https://pagespeed.web.dev/analysis/https-hydur-com/04q3parnzo?form_factor=desktop | I37: https://pagespeed.web.dev/analysis/https-hydur-com-collections-all/skd7iggltf?form_factor=desktop | J37: https://pagespeed.web.dev/analysis/https-hydur-com-collections-all-products-10ml-black-orchid-inspired-by-velvet-orchid-by-tom-ford-1/hq35dcmcqd?form_factor=desktop
A38: https://elektusdivision.com | B38: WEBSITE CLOSED
A39: https://aorahstudio.com | B39: 73 | C39: 89 | D39: 73 | E39: 96 | F39: 78 | G39: 90 | H39: https://pagespeed.web.dev/analysis/https-www-aorahstudio-com/9mx188ojhz?form_factor=desktop | I39: https://pagespeed.web.dev/analysis/https-www-aorahstudio-com-collections-all/s3k5p93s35?form_factor=desktop | J39: https://pagespeed.web.dev/analysis/https-www-aorahstudio-com-products-ebira-fringe-cropped-jacket/zk31arativ?form_factor=mobile
A40: https://cruiselife.com | B40: 80 | C40: 65 | D40: 65 | E40: 78 | F40: 65 | G40: 86 | H40: https://pagespeed.web.dev/analysis/https-cruiselife-com/s09bbgi364?form_factor=desktop | I40: https://pagespeed.web.dev/analysis/https-cruiselife-com-collections-all/7madvt2tb1?form_factor=desktop | J40: https://pagespeed.web.dev/analysis/https-cruiselife-com-products-women-beige-club-embroidered-hoodie/dpl6msgho7?form_factor=desktop
A41: https://awaythatday.com | B41: 47 | C41: 34 | D41: 33 | E41: 38 | F41: 45 | G41: 43 | H41: https://pagespeed.web.dev/analysis/https-awaythatday-com/4kvo3w8in6?form_factor=desktop | I41: https://pagespeed.web.dev/analysis/https-awaythatday-com-collections-all/exxw617xlg?form_factor=mobile | J41: https://pagespeed.web.dev/analysis/https-awaythatday-com-products-acapulco-bottom-polka-dot-rose/kt3dhmuu9v?form_factor=desktop
A42: https://ifonlyif.co.uk | B42: 27 | C42: 31 | D42: error | E42: error | F42: 27 | G42: 40 | H42: https://pagespeed.web.dev/analysis/https-ifonlyif-co-uk/bjc9qghmsm?form_factor=desktop | J42: https://pagespeed.web.dev/analysis/https-ifonlyif-co-uk-products-pandora-buttercup-yellow-gingham/t3dxgf2gv8?form_factor=desktop
A43: https://caramel-shop.co.uk | B43: 47 | C43: 51 | D43: 50 | E43: 55 | F43: 58 | G43: 63 | H43: https://pagespeed.web.dev/analysis/https-www-caramel-shop-co-uk/xi0jc875sb?form_factor=desktop | I43: https://pagespeed.web.dev/analysis/https-www-caramel-shop-co-uk-collections-all/wmwtykvb13?form_factor=desktop | J43: https://pagespeed.web.dev/analysis/https-www-caramel-shop-co-uk-collections-all-products-delilah-girls-cotton-dress-sushi-vintage-floral/gno2d93jhq?form_factor=desktop
A44: https://irregularchoice.com | B44: 39 | C44: 72 | D44: 73 | E44: 93 | F44: 73 | G44: 95 | H44: https://pagespeed.web.dev/analysis/https-irregularchoice-com/di3r7ggbuc?form_factor=desktop | I44: https://pagespeed.web.dev/analysis/https-irregularchoice-com-categories-everything/11de8qts19?form_factor=desktop | J44: https://pagespeed.web.dev/analysis/https-irregularchoice-com-products-eat-me-b-pastel-brocade-gold-pearly-tea-party-shoes/0iy6ibv2pd?form_factor=desktop
A45: https://harrysoflondon.com | B45: 40 | C45: 38 | D45: 31 | E45: 45 | F45: 41 | G45: 49 | H45: https://pagespeed.web.dev/analysis/https-harrysoflondon-com/kxh57bowvw?form_factor=desktop | I45: https://pagespeed.web.dev/analysis/https-harrysoflondon-com-collections-all/pi2h5nk10g?form_factor=desktop | J45: https://pagespeed.web.dev/analysis/https-harrysoflondon-com-products-aaron-l-1/316ijvwlci?form_factor=desktop
A46: https://weardala.com | B46: 56 | C46: 64 | D46: 55 | E46: 45 | F46: 54 | G46: 72 | H46: https://pagespeed.web.dev/analysis/https-weardala-com/miucu619wo?form_factor=desktop | I46: https://pagespeed.web.dev/analysis/https-weardala-com-collections-all/alc4kjej83?form_factor=desktop | J46: https://pagespeed.web.dev/analysis/https-weardala-com-collections-all-products-sling-jeans-salt/envumt3y9h?form_factor=desktop
A47: https://cupiob.com | B47: 74 | C47: 94 | D47: 74 | E47: 99 | F47: 79 | G47: 99 | H47: https://pagespeed.web.dev/analysis/https-cupiob-com/61fapwhk0y?form_factor=desktop | I47: https://pagespeed.web.dev/analysis/https-cupiob-com-collections-all/shk1dp9dff?form_factor=mobile | J47: https://pagespeed.web.dev/analysis/https-cupiob-com-products-spinning-eye-pendant-with-silver-beads/wbtezwo1tp?form_factor=desktop
A48: https://bsideldn.com | B48: 66 | C48: 69 | D48: NA | E48: NA | F48: NA | G48: NA | H48: https://pagespeed.web.dev/analysis/https-waleadeyemi-com-password/fktq4b0a0w?form_factor=desktop | I48: NA | J48: NA
A49: https://apexworkwear.co.uk | B49: 47 | C49: 55 | D49: 40 | E49: 46 | F49: 33 | G49: 52 | H49: https://pagespeed.web.dev/analysis/https-apexworkwear-co-uk/ru5w3pbdhv?form_factor=desktop | I49: https://pagespeed.web.dev/analysis/https-apexworkwear-co-uk-collections-all/abrwddj5gi?form_factor=mobile | J49: https://pagespeed.web.dev/analysis/https-apexworkwear-co-uk-products-ladies-trousers-healthcare-straight-leg/ubrv6syude?form_factor=desktop
A50: https://fouroz.com | B50: 48 | C50: 63 | D50: 39 | E50: 50 | F50: 49 | G50: 68 | H50: https://pagespeed.web.dev/analysis/https-fouroz-com/kzp4qrc295?form_factor=desktop | I50: https://pagespeed.web.dev/analysis/https-fouroz-com-collections-all/8g1xb78wbi?form_factor=desktop | J50: https://pagespeed.web.dev/analysis/https-fouroz-com-products-allure-white-tshirt/35fccricbv?form_factor=desktop
A51: https://28club.co.uk | B51: 56 | C51: 75 | D51: NA | E51: NA | F51: NA | G51: NA | H51: https://pagespeed.web.dev/analysis/https-28club-co-uk-password/v2mdg41zam?form_factor=desktop | I51: NA | J51: NA
A52: https://101p100.com | B52: 62 | C52: 73 | D52: 59 | E52: 77 | F52: 23 | G52: 84 | H52: https://pagespeed.web.dev/analysis/https-101p100-com/17e4yvaq16?form_factor=mobile | I52: https://pagespeed.web.dev/analysis/https-101p100-com-collections-all/qlnxmhghr7?form_factor=mobile | J52: https://pagespeed.web.dev/analysis/https-101p100-com-products-acai-racer-back-maxi-dress/4sn60y6tjc?form_factor=mobile
A53: https://andsons.co.uk | B53: 87 | C53: 64 | D53: 92 | E53: 95 | F53: 72 | G53: 92 | H53: https://pagespeed.web.dev/analysis/https-andsons-co-uk/sap0wzcj8u?form_factor=desktop | I53: https://pagespeed.web.dev/analysis/https-andsons-co-uk-collections-all/w837l5d77t?form_factor=mobile | J53: https://pagespeed.web.dev/analysis/https-andsons-co-uk-products-sons-sunday-shirt-utility-navy/5uhlzsyk4i?form_factor=mobile
A54: https://16arlington.co.uk | B54: 49 | C54: 51 | D54: 52 | E54: 45 | F54: 57 | G54: 33 | H54: https://pagespeed.web.dev/analysis/https-16arlington-co-uk/2z27lurqln?form_factor=mobile | I54: https://pagespeed.web.dev/analysis/https-yourmusa-com-collections-all/ck89hul5k7?form_factor=desktop | J54: https://pagespeed.web.dev/analysis/https-yourmusa-com-products-antique-corset-green-tapestry/ol71q2kir2?form_factor=desktop
A55: https://28natelier.com | B55: 60 | C55: 45 | D55: 53 | E55: 61 | F55: 46 | G55: 53 | H55: https://pagespeed.web.dev/analysis/https-28natelier-com/d6prus8pao?form_factor=desktop | I55: https://pagespeed.web.dev/analysis/https-28natelier-com-collections-all/6vtdygzx62?form_factor=mobile | J55: https://pagespeed.web.dev/analysis/https-28natelier-com-products-big-button-energy-dress/qclp6vesph?form_factor=mobile
A56: https://2bigfeet.com | B56: 57 | C56: 69 | D56: 39 | E56: 54 | F56: 28 | G56: 94 | H56: https://pagespeed.web.dev/analysis/https-www-2bigfeet-com/15nqsa9fid?form_factor=mobile | I56: https://pagespeed.web.dev/analysis/https-www-2bigfeet-com-collections-all/8rxdjyjyam?form_factor=desktop | J56: https://pagespeed.web.dev/analysis/https-www-2bigfeet-com-collections-all-products-2bigfeet-25th-anniversary-t-shirt-dark-heather-grey/fub0ynvvet?form_factor=desktop
A57: https://33-mm.com | B57: 53 | C57: 75 | D57: 28 | E57: 37 | F57: 43 | G57: 59 | H57: https://pagespeed.web.dev/analysis/https-www-33-mm-com/nh2x3irz2n?form_factor=desktop | I57: https://pagespeed.web.dev/analysis/https-www-33-mm-com-collections-all/f4e9rjxgp2?form_factor=desktop | J57: https://pagespeed.web.dev/analysis/https-www-33-mm-com-products-altair-gold/59d5hvkux4?form_factor=mobile
A58: https://3qworkwear.co.uk | B58: 47 | C58: 58 | D58: 54 | E58: 56 | F58: 43 | G58: 65 | H58: https://pagespeed.web.dev/analysis/https-www-3qworkwear-co-uk/skd27ejl6p?form_factor=desktop | I58: https://pagespeed.web.dev/analysis/https-www-3qworkwear-co-uk-collections-all/d2ymrh1k8a?form_factor=desktop | J58: https://pagespeed.web.dev/analysis/https-www-3qworkwear-co-uk-products-abbins-maintenance-russell-hooded-sweatshirt/k3t9qwbzb4?form_factor=desktop
A59: https://3rdrockclothing.com | B59: WEBSITE UNDER MAINTENANCE
A60: https://iv74.com | B60: 86 | C60: 68 | D60: 71 | E60: 84 | F60: 76 | G60: 95 | H60: https://pagespeed.web.dev/analysis/https-iv74-com/1dqcte6cf6?form_factor=desktop | I60: https://pagespeed.web.dev/analysis/https-iv74-com-collections-all/ko52o78zbg?form_factor=desktop | J60: https://pagespeed.web.dev/analysis/https-iv74-com-products-organic-oversized-cropped-t-shirt-mint-green/45vkb3cwgp?form_factor=desktop
A61: https://69bboutique.com | B61: 58 | C61: 61 | D61: 69 | E61: 93 | F61: 65 | G61: 85 | H61: https://pagespeed.web.dev/analysis/https-69bpetboutique-com/9jtb3jjvvx?form_factor=desktop | I61: https://pagespeed.web.dev/analysis/https-69bpetboutique-com-collections-all/8y9yfmtc2y?form_factor=desktop | J61: https://pagespeed.web.dev/analysis/https-69bpetboutique-com-products-3-blind-mice-cat-toy/o8wjnr3spe?form_factor=mobile
...

Sheet Backup-Shuvojit
A1: Owner | B1: Website | C1: Home Page | E1: Collection Page | G1: Product Details Page | I1: Page Speed URLs
C2: Mobile | D2: Desktop | E2: Mobile | F2: Desktop | G2: Mobile | H2: Desktop | I2: Home Page | J2: Collection Page | K2: PDP
A3: =VLOOKUP(TRIM(B3),Hrisikesh!A:B,2,0) -> 31 | B3: https://spiralusa.com | C3: 31 | D3: 42 | E3: 30 | F3: 34 | G3: 29 | H3: 37 | I3: https://pagespeed.web.dev/analysis/https-www-spiralusa-com/8hz3ye3ry4?form_factor=desktop | J3: https://pagespeed.web.dev/analysis/https-www-spiralusa-com-collections-all/rgozhg8xd8?form_factor=desktop | K3: https://pagespeed.web.dev/analysis/https-www-spiralusa-com-products-system-of-a-down-hand-t-shirt-black/onp405zaon?form_factor=desktop
A4: =VLOOKUP(TRIM(B4),Hrisikesh!A:B,2,0) -> 26 | B4: https://matchlesslondon.com | C4: 26 | D4: 44 | E4: 23 | F4: 44 | G4: NA | H4: NA | I4: https://pagespeed.web.dev/analysis/https-matchlesslondon-com-pages-boutique/nh3t3naxgo?form_factor=desktop | J4: https://pagespeed.web.dev/analysis/https-matchlesslondon-com/pe7e51wyiu?form_factor=mobile | K4: NA
A5: =VLOOKUP(TRIM(B5),Hrisikesh!A:B,2,0) -> 28 | B5: https://youngsoles.com | C5: 28 | D5: 46 | E5: 53 | F5: 63 | G5: 22 | H5: 56 | I5: https://pagespeed.web.dev/analysis/https-www-youngsoles-com/imi3ntt235?form_factor=desktop | J5: https://pagespeed.web.dev/analysis/https-www-youngsoles-com-collections-all/gy23vd05yr?form_factor=desktop | K5: https://pagespeed.web.dev/analysis/https-www-youngsoles-com-products-penny-kids-shoe-black/pvrhk3nzex?form_factor=mobile
A6: =VLOOKUP(TRIM(B6),Hrisikesh!A:B,2,0) -> 48 | B6: https://areweoblivious.com | C6: 48 | D6: 62 | E6: 40 | F6: 71 | G6: 51 | H6: 47 | I6: https://pagespeed.web.dev/analysis/https-www-areweoblivious-com/cs7gt7hzad?form_factor=desktop | J6: https://pagespeed.web.dev/analysis/https-www-areweoblivious-com-collections-all/k16xa40nqs?form_factor=desktop | K6: https://pagespeed.web.dev/analysis/https-www-areweoblivious-com-products-who-cares-what-other-people-think-dark-green-t-shirt/u2bzkbh6z5?form_factor=desktop
A7: =VLOOKUP(TRIM(B7),Hrisikesh!A:B,2,0) -> 49 | B7: https://samuel-windsor.co.uk | C7: 49 | D7: 80 | E7: 58 | F7: 78 | G7: 45 | H7: 62 | I7: https://pagespeed.web.dev/analysis/https-www-samuel-windsor-co-uk/w3xzxkvx6o?form_factor=desktop | J7: https://pagespeed.web.dev/analysis/https-www-samuel-windsor-co-uk-collections-all/h4jutivwll?form_factor=desktop | K7: https://pagespeed.web.dev/analysis/https-www-samuel-windsor-co-uk-products-admiral-deck-shoe-brown/dw99q9f3im?form_factor=desktop
A8: =VLOOKUP(TRIM(B8),Hrisikesh!A:B,2,0) -> 43 | B8: https://rebelliousfashion.com | C8: 43 | D8: 76 | E8: 38 | F8: 45 | G8: 24 | H8: 63 | I8: https://pagespeed.web.dev/analysis/https-rebelliousfashion-com/9043cghita?form_factor=desktop | J8: https://pagespeed.web.dev/analysis/https-rebelliousfashion-com-collections-all/kcduob2219?form_factor=desktop | K8: https://pagespeed.web.dev/analysis/https-rebelliousfashion-com-products-black-tailored-blazer-playsuit-minzi/oni33b68tw?form_factor=desktop
A9: =VLOOKUP(TRIM(B9),Hrisikesh!A:B,2,0) -> 43 | B9: https://lalagebeaumont.com | C9: 43 | D9: 61 | E9: 41 | F9: 54 | G9: 33 | H9: 45 | I9: https://pagespeed.web.dev/analysis/https-lalagebeaumont-com/5cym3plnh0?form_factor=desktop | J9: https://pagespeed.web.dev/analysis/https-lalagebeaumont-com-collections-all/lle02qqn68?form_factor=desktop | K9: https://pagespeed.web.dev/analysis/https-lalagebeaumont-com-products-12mm-mother-of-pearl-stud-earrings-pink/uek7osufue?form_factor=mobile
A10: =VLOOKUP(TRIM(B10),Hrisikesh!A:B,2,0) -> 56 | B10: https://luxurypromise.com | C10: 56 | D10: 39 | E10: 44 | F10: 53 | G10: 38 | H10: 61 | I10: https://pagespeed.web.dev/analysis/https-luxurypromise-com/18dfht6cll?form_factor=desktop | J10: https://pagespeed.web.dev/analysis/https-luxurypromise-com-collections-all/ljowrjxjkd?form_factor=mobile | K10: https://pagespeed.web.dev/analysis/https-luxurypromise-com-collections-all-products-new-birkin-shoulder-29-poussiere-evercolor-permabrass-hardware-stamp-k-full-set-original-receipt-sycf1561/h4gmr0qgdp?form_factor=desktop
A11: =VLOOKUP(TRIM(B11),Hrisikesh!A:B,2,0) -> 40 | B11: https://revivalvintage.co.uk | C11: 40 | D11: 65 | E11: 37 | F11: 33 | G11: 35 | H11: 61 | I11: https://pagespeed.web.dev/analysis/https-revivalvintage-co-uk/uhfzpsepd8?form_factor=mobile | J11: https://pagespeed.web.dev/analysis/https-revivalvintage-co-uk-collections-all/3hganywbdc?form_factor=desktop | K11: https://pagespeed.web.dev/analysis/https-revivalvintage-co-uk-products-1940s-deliverance-demob-jacket-blue-herringbone/udi4r8dbgu?form_factor=mobile
A12: =VLOOKUP(TRIM(B12),Hrisikesh!A:B,2,0) -> 14 | B12: https://universalworks.com | C12: 14 | D12: 42 | E12: 36 | F12: 45 | G12: 20 | H12: 51 | I12: https://pagespeed.web.dev/analysis/https-universalworks-com/5a4gdo4ina?form_factor=desktop | J12: https://pagespeed.web.dev/analysis/https-universalworks-com/cixkb0tobf?form_factor=mobile | K12: https://pagespeed.web.dev/analysis/https-universalworks-com-products-dark-navy-ospina-cotton-oxford-pant/ji9ll02n9w?form_factor=desktop
A13: =VLOOKUP(TRIM(B13),Hrisikesh!A:B,2,0) -> 54 | B13: https://wiggykit.com | C13: 54 | D13: 63 | E13: 52 | F13: 54 | G13: 61 | H13: 78 | I13: https://pagespeed.web.dev/analysis/https-www-wiggykit-com/kphqpihbef?form_factor=desktop | J13: https://pagespeed.web.dev/analysis/https-www-wiggykit-com-collections-all/zdgtyecvcq?form_factor=desktop | K13: https://pagespeed.web.dev/analysis/https-www-wiggykit-com-products-the-keeper-dress/e3trv0anin?form_factor=desktop
A14: =VLOOKUP(TRIM(B14),Hrisikesh!A:B,2,0) -> 45 | B14: https://privatewhitevc.com | C14: 45 | D14: 59 | E14: 29 | F14: 44 | G14: 36 | H14: 42 | I14: https://pagespeed.web.dev/analysis/https-www-privatewhitevc-com/ggzg100el1?form_factor=mobile | J14: https://pagespeed.web.dev/analysis/https-www-privatewhitevc-com-collections-all/f6y4aben3z?form_factor=desktop | K14: https://pagespeed.web.dev/analysis/https-www-privatewhitevc-com-products-the-submariner-parka-1/ugsaofwpih?form_factor=desktop
A15: =VLOOKUP(TRIM(B15),Hrisikesh!A:B,2,0) -> 58 | B15: https://palaceofnowhere.co.uk | C15: 58 | D15: 25 | E15: 65 | F15: 74 | G15: 62 | H15: 64 | I15: https://pagespeed.web.dev/analysis/https-palaceofnowhere-co-uk/2ffurvjenf?form_factor=desktop | J15: https://pagespeed.web.dev/analysis/https-palaceofnowhere-co-uk-collections-all/9gxd3nwsm5?form_factor=desktop | K15: https://pagespeed.web.dev/analysis/https-palaceofnowhere-co-uk-products-2-x-vintage-60s-verrerie-d-arques-pressed-glass-candle-holders/tfkbkd7ouq?form_factor=desktop
A16: =VLOOKUP(TRIM(B16),Hrisikesh!A:B,2,0) -> 47 | B16: https://thrifted.com | C16: 47 | D16: 36 | E16: 33 | F16: 48 | G16: 38 | H16: 62 | I16: https://pagespeed.web.dev/analysis/https-www-thrifted-com/rdxsyvn1e8?form_factor=desktop | J16: https://pagespeed.web.dev/analysis/https-www-thrifted-com-collections-all/elr7v7grs1?form_factor=mobile | K16: https://pagespeed.web.dev/analysis/https-www-thrifted-com-products-southern-new-hampshire-university-champion-hoodie-mens-grey-small-61353-a-new/hgzufyoubd?form_factor=desktop
... A41: =VLOOKUP(TRIM(B41),Hrisikesh!A:B,2,0) -> 54 | B41: https://room24.co.uk | C41: 54 | D41: 58 | E41: 68 | F41: 86 | G41: 54 | H41: 64 | I41: https://pagespeed.web.dev/analysis/https-room24-co-uk/kjgoqduvg5?form_factor=mobile | J41: https://pagespeed.web.dev/analysis/https-room24-co-uk-collections-all/yq3sq57pnm?form_factor=desktop | K41: https://pagespeed.web.dev/analysis/https-room24-co-uk-products-alexa-one-piece-black-copy/8flumb29n8?form_factor=desktop
A42: =VLOOKUP(TRIM(B42),Hrisikesh!A:B,2,0) -> 28 | B42: https://oliviavonhalle.com | C42: 28 | D42: 35 | E42: 30 | F42: 27 | G42: 28 | H42: 63 | I42: https://pagespeed.web.dev/analysis/https-oliviavonhalle-com/c6kahtlg7s?form_factor=desktop | J42: https://pagespeed.web.dev/analysis/https-oliviavonhalle-com-collections-all/ceqpchfb99?form_factor=desktop
A43: =VLOOKUP(TRIM(B43),Hrisikesh!A:B,2,0) -> 56 | B43: https://luxurypromise.com | C43: 32 | D43: 37 | E43: 42 | F43: 59 | G43: 53 | H43: 65 | I43: https://pagespeed.web.dev/analysis/https-luxurypromise-com/e09nkttvxz?form_factor=desktop | J43: https://pagespeed.web.dev/analysis/https-luxurypromise-com-collections-all/i57szil3ku?form_factor=desktop | K43: https://pagespeed.web.dev/analysis/https-luxurypromise-com-collections-all-products-vintage-chanel-classic-flap-medium-chain-shoulder-bag-red-lamb-skin-gold-hardware-90308215/dzjx8pdnde?form_factor=desktop
A44: =VLOOKUP(TRIM(B44),Hrisikesh!A:B,2,0) -> 49 | B44: https://tocoswim.com | C44: 49 | D44: 63 | E44: 46 | F44: 37 | G44: 28 | H44: 63 | I44: https://pagespeed.web.dev/analysis/https-tocoswim-com/nl0ss802eb?form_factor=desktop | J44: https://pagespeed.web.dev/analysis/https-tocoswim-com-collections-all/fsby7qqgcv?form_factor=desktop | K44: https://pagespeed.web.dev/analysis/https-tocoswim-com-products-agni-halter-neck-triangle-bikini-top-picante-red-pink-gold-flower-print/mktiwu8n14?form_factor=desktop
A45: =VLOOKUP(TRIM(B45),Hrisikesh!A:B,2,0) -> 47 | B45: https://pomodoroclothing.com | C45: 47 | D45: 80 | E45: 87 | F45: 98 | G45: NA | H45: NA | I45: https://pagespeed.web.dev/analysis/https-www-pomodoroclothing-com/hu1oz4dioi?form_factor=desktop | J45: https://pagespeed.web.dev/analysis/https-www-pomodoroclothing-com-pages-collection/0juzywprgc?form_factor=desktop | K45: NA
A46: =VLOOKUP(TRIM(B46),Hrisikesh!A:B,2,0) -> 36 | B46: https://paradoxlondon.com | C46: 36 | D46: 44 | E46: 37 | F46: 49 | G46: 39 | H46: 40 | I46: https://pagespeed.web.dev/analysis/https-www-paradoxlondon-com/11cngkxkxs?form_factor=desktop | J46: https://pagespeed.web.dev/analysis/https-www-paradoxlondon-com-collections-all/28y21wknq6?form_factor=desktop | K46: https://pagespeed.web.dev/analysis/https-www-paradoxlondon-com-products-adorn-ivory-wide-fit-satin-block-heel-wedding-shoes/fpcltt9us5?form_factor=desktop
A47: =VLOOKUP(TRIM(B47),Hrisikesh!A:B,2,0) -> 58 | B47: https://maharishistore.com | C47: 58 | D47: 67 | E47: 47 | F47: 68 | G47: 46 | H47: 58 | I47: https://pagespeed.web.dev/analysis/https-www-maharishistore-com/yjapzv6t8q?form_factor=desktop | J47: https://pagespeed.web.dev/analysis/https-www-maharishistore-com-collections-all/oepv8dwkyg?form_factor=desktop | K47: https://pagespeed.web.dev/analysis/https-www-maharishistore-com-products-1113-maha-malice-monk-sling-bag-olive/etkhpaz2f0?form_factor=desktop
A48: =VLOOKUP(TRIM(B48),Hrisikesh!A:B,2,0) -> 34 | B48: https://stripeandstare.com | C48: 34 | D48: 60 | E48: 31 | F48: 53 | G48: 30 | H48: 44 | I48: https://pagespeed.web.dev/analysis/https-stripeandstare-com/8wycfqlzmw?form_factor=desktop | J48: https://pagespeed.web.dev/analysis/https-stripeandstare-com/3bellsl5eb?form_factor=desktop | K48: https://pagespeed.web.dev/analysis/https-stripeandstare-com-products-triangle-lace-bra-black/9n9wjlsz14?form_factor=desktop
A49: =VLOOKUP(TRIM(B49),Hrisikesh!A:B,2,0) -> 96 | B49: https://exude.in | C49: 96 | D49: 88 | E49: 55 | F49: 58 | G49: 83 | H49: 58 | I49: https://pagespeed.web.dev/analysis/https-www-exude-in/uwet1xr4sh?form_factor=desktop | J49: https://pagespeed.web.dev/analysis/https-www-exude-in-collections-all/8azg1wmgyo?form_factor=desktop | K49: https://pagespeed.web.dev/analysis/https-www-exude-in-products-black-ribbed-peplum-co-ord-set-choker-neck-top-wide-leg-pants/jt7m1y98mf?form_factor=desktop
A50: =VLOOKUP(TRIM(B50),Hrisikesh!A:B,2,0) -> 40 | B50: https://mariechantal.com | C50: 40 | D50: 40 | E50: 29 | F50: 42 | G50: 29 | H50: 39 | I50: https://pagespeed.web.dev/analysis/https-www-mariechantal-com/5dxtyht406?form_factor=desktop | J50: https://pagespeed.web.dev/analysis/https-www-mariechantal-com-collections-all/29uhizocdu?form_factor=desktop | K50: https://pagespeed.web.dev/analysis/https-www-mariechantal-com-products-camille-tennis-baby-jumper-pink/ly8xgdldf1?form_factor=desktop
A51: =VLOOKUP(TRIM(B51),Hrisikesh!A:B,2,0) -> 34 | B51: https://peachyden.co.uk | C51: 34 | D51: 78 | E51: 53 | F51: 53 | G51: 40 | H51: 34 | I51: https://pagespeed.web.dev/analysis/https-www-peachyden-co-uk/srrhu3eni7?form_factor=desktop | J51: https://pagespeed.web.dev/analysis/https-www-peachyden-co-uk-collections-all-products/w12lk7l93l?form_factor=desktop | K51: https://pagespeed.web.dev/analysis/https-www-peachyden-co-uk-collections-all-products-products-the-cindy-halter-top-fir-tree/qtdkuegq1b?form_factor=mobile
A52: =VLOOKUP(TRIM(B52),Hrisikesh!A:B,2,0) -> 49 | B52: https://theunseenlabel.com | C52: 49 | D52: 77 | E52: 57 | F52: 62 | G52: 54 | H52: 76 | I52: https://pagespeed.web.dev/analysis/https-theunseenlabel-com/foabbytnts?form_factor=desktop | J52: https://pagespeed.web.dev/analysis/https-theunseenlabel-com-collections-all/bm3hcdx7is?form_factor=desktop | K52: https://pagespeed.web.dev/analysis/https-theunseenlabel-com-collections-all-products-the-ease-bra-1/v6ji46gwsm?form_factor=desktop
A53: =VLOOKUP(TRIM(B53),Hrisikesh!A:B,2,0) -> #N/A | B53: https://edenmaystudio.co.uk | C53: ASKING FOR SIGNUP
A54: =VLOOKUP(TRIM(B54),Hrisikesh!A:B,2,0) -> #N/A | B54: https://fashioneyewear.com | C54: 29 | D54: 38 | E54: 33 | F54: 44 | G54: 6 | H54: 53 | I54: https://pagespeed.web.dev/analysis/https-www-fashioneyewear-com-en-in/smmpv9gz53?form_factor=desktop | J54: https://pagespeed.web.dev/analysis/https-www-fashioneyewear-com-en-in-collections-all/2rgcyj22yo?form_factor=desktop | K54: https://pagespeed.web.dev/analysis/https-www-fashioneyewear-com-en-in-products-adidas-sp0063/awlwfcwwml?form_factor=mobile
A55: =VLOOKUP(TRIM(B55),Hrisikesh!A:B,2,0) -> #N/A | B55: https://buttahlondon.com | C55: 34 | D55: 57 | E55: 49 | F55: 54 | G55: 48 | H55: 70 | I55: https://pagespeed.web.dev/analysis/https-buttahlondon-com/b0o780lgib?form_factor=desktop | J55: https://pagespeed.web.dev/analysis/https-buttahlondon-com-collections-all/fy3lhyzo4y?form_factor=desktop | K55: https://pagespeed.web.dev/analysis/https-buttahlondon-com-products-long-tank-top/jup1sr8f6v?form_factor=desktop
A56: =VLOOKUP(TRIM(B56),Hrisikesh!A:B,2,0) -> #N/A | B56: https://ayamset.com | C56: 75 | D56: 85 | E56: 66 | F56: 88 | G56: 37 | H56: 55 | I56: https://pagespeed.web.dev/analysis/https-ayamset-com/ghd1mbubew?form_factor=mobile | J56: https://pagespeed.web.dev/analysis/https-ayamset-com-collections-all/dloiqcf0n0?form_factor=desktop | K56: https://pagespeed.web.dev/analysis/https-www-mytheresa-com-gb-en-women-marant-etoile-anasta-faux-fur-jacket-brown-p01003106/xv6fz84x69?form_factor=desktop
A57: =VLOOKUP(TRIM(B57),Hrisikesh!A:B,2,0) -> #N/A | B57: https://ibizafashionfestival.com | C57: 75 | D57: 97 | E57: 89 | F57: 99 | G57: 78 | H57: 91 | I57: https://pagespeed.web.dev/analysis/https-ibizafashionfestival-com/e33cb5be8o?form_factor=desktop | J57: https://pagespeed.web.dev/analysis/https-ibizafashionfestival-com-collections-all/16y6eo6i3n?form_factor=desktop | K57: https://pagespeed.web.dev/analysis/https-ibizafashionfestival-com-products-cassandra-swimsuit-copy/znkm6poqc4?form_factor=desktop
A58: =VLOOKUP(TRIM(B58),Hrisikesh!A:B,2,0) -> #N/A | B58: https://comhla.co.uk | C58: 58 | D58: 74 | E58: 60 | F58: 67 | G58: 60 | H58: 65 | I58: https://pagespeed.web.dev/analysis/https-comhla-co-uk/xj3mhzjg69?form_factor=mobile | J58: https://pagespeed.web.dev/analysis/https-comhla-co-uk-collections-women-Buy-Well/snijwz3gka?form_factor=desktop | K58: https://pagespeed.web.dev/analysis/https-comhla-co-uk-products-large-merino-triangle-scarf-in-red-stripe/erkz3kzv1y?form_factor=desktop
A59: =VLOOKUP(TRIM(B59),Hrisikesh!A:B,2,0) -> #N/A | B59: https://abtany.com | C59: 69 | D59: 76 | E59: 78 | F59: 95 | G59: 72 | H59: 61 | I59: https://pagespeed.web.dev/analysis/https-www-abtany-com/cknuwkkg17?form_factor=desktop | J59: https://pagespeed.web.dev/analysis/https-www-abtany-com-collections-all/c6tj7iijfh?form_factor=desktop | K59: https://pagespeed.web.dev/analysis/https-www-abtany-com-products-black-drawstring-swim-shorts-copy/oota3tca4a?form_factor=desktop
A60: =VLOOKUP(TRIM(B60),Hrisikesh!A:B,2,0) -> #N/A | B60: https://heidiklein.com | C60: 67 | D60: 85 | E60: 45 | F60: 55 | G60: 62 | H60: 82 | I60: https://pagespeed.web.dev/analysis/https-heidiklein-com/y52ob8p4bk?form_factor=desktop | J60: https://pagespeed.web.dev/analysis/https-heidiklein-com-collections-all/p1u9jza6ae?form_factor=desktop | K60: https://pagespeed.web.dev/analysis/https-heidiklein-com-products-at-lace-beach-shirt/wtdlriagb2?form_factor=desktop
A61: =VLOOKUP(TRIM(B61),Hrisikesh!A:B,2,0) -> #N/A | B61: https://bbxbrand.com | C61: 21 | D61: 40 | E61: 38 | F61: 44 | G61: 42 | H61: 54 | I61: https://pagespeed.web.dev/analysis/https-www-bbxbrand-com/kf5ktzowl3?form_factor=desktop | J61: https://pagespeed.web.dev/analysis/https-www-bbxbrand-com-collections-all/wokjoidnfs?form_factor=desktop | K61: https://pagespeed.web.dev/analysis/https-www-bbxbrand-com-collections-all-products-waterfall-mini-lime-green/nf1bqiej49?form_factor=desktop
A62: =VLOOKUP(TRIM(B62),Hrisikesh!A:B,2,0) -> #N/A | B62: https://amelry.com | C62: 68 | D62: 66 | E62: 65 | F62: 74 | G62: 60 | H62: 63 | I62: https://pagespeed.web.dev/analysis/https-amelry-com/4njxzoa9n9?form_factor=desktop | J62: https://pagespeed.web.dev/analysis/https-palaceofnowhere-co-uk-collections-all/9gxd3nwsm5?form_factor=mobile | K62: https://pagespeed.web.dev/analysis/https-amelry-com-products-beige-shirred-dress/0u2uq28kic?form_factor=desktop
A63: =VLOOKUP(TRIM(B63),Hrisikesh!A:B,2,0) -> #N/A | B63: https://havvamustafa.com | C63: 58 | D63: 87 | E63: 71 | F63: 53 | G63: 61 | H63: 76 | I63: https://pagespeed.web.dev/analysis/https-havvamustafa-com/8g2oxt6b74?form_factor=desktop | J63: https://pagespeed.web.dev/analysis/https-havvamustafa-com-collections-all/m1s1qj7w18?form_factor=desktop | K63: https://pagespeed.web.dev/analysis/https-havvamustafa-com-collections-all-products-netto-texas-tall-black/dmuejrxh7w?form_factor=desktop
A64: =VLOOKUP(TRIM(B64),Hrisikesh!A:B,2,0) -> #N/A | B64: https://farafieldclothing.com | C64: 52 | D64: 65 | E64: 51 | F64: 63 | G64: 43 | H64: 50 | I64: https://pagespeed.web.dev/analysis/https-farafieldclothing-com/lsp3w2q7io?form_factor=desktop | J64: https://pagespeed.web.dev/analysis/https-farafieldclothing-com/1nvi3bc49h?form_factor=desktop | K64: https://pagespeed.web.dev/analysis/https-farafieldclothing-com-products-aleksey-horace-zip-sand/kuxk4k7vqz?form_factor=desktop
...

Sheet Hrisikesh
A1: Website | B1: Home Page | D1: Collection Page | F1: Product Details Page | H1: Page Speed URLs
B2: Mobile | C2: Desktop | D2: Mobile | E2: Desktop | F2: Mobile | G2: Desktop | H2: Home Page | I2: Collection Page | J2: PDP
A3: https://spiralusa.com | B3: 31 | C3: 42 | D3: 30 | E3: 34 | F3: 29 | G3: 37 | H3: https://pagespeed.web.dev/analysis/https-www-spiralusa-com/8hz3ye3ry4?form_factor=desktop | I3: https://pagespeed.web.dev/analysis/https-www-spiralusa-com-collections-all/rgozhg8xd8?form_factor=desktop | J3: https://pagespeed.web.dev/analysis/https-www-spiralusa-com-products-system-of-a-down-hand-t-shirt-black/onp405zaon?form_factor=desktop
A4: https://matchlesslondon.com | B4: 26 | C4: 44 | D4: 23 | E4: 44 | F4: NA | G4: NA | H4: https://pagespeed.web.dev/analysis/https-matchlesslondon-com-pages-boutique/nh3t3naxgo?form_factor=desktop | I4: https://pagespeed.web.dev/analysis/https-matchlesslondon-com/pe7e51wyiu?form_factor=mobile | J4: NA
A5: https://youngsoles.com | B5: 28 | C5: 46 | D5: 53 | E5: 63 | F5: 22 | G5: 56 | H5: https://pagespeed.web.dev/analysis/https-www-youngsoles-com/imi3ntt235?form_factor=desktop | I5: https://pagespeed.web.dev/analysis/https-www-youngsoles-com-collections-all/gy23vd05yr?form_factor=desktop | J5: https://pagespeed.web.dev/analysis/https-www-youngsoles-com-products-penny-kids-shoe-black/pvrhk3nzex?form_factor=mobile
A6: https://areweoblivious.com | B6: 48 | C6: 62 | D6: 40 | E6: 71 | F6: 51 | G6: 47 | H6: https://pagespeed.web.dev/analysis/https-www-areweoblivious-com/cs7gt7hzad?form_factor=desktop | I6: https://pagespeed.web.dev/analysis/https-www-areweoblivious-com-collections-all/k16xa40nqs?form_factor=desktop | J6: https://pagespeed.web.dev/analysis/https-www-areweoblivious-com-products-who-cares-what-other-people-think-dark-green-t-shirt/u2bzkbh6z5?form_factor=desktop
A7: https://samuel-windsor.co.uk | B7: 49 | C7: 80 | D7: 58 | E7: 78 | F7: 45 | G7: 62 | H7: https://pagespeed.web.dev/analysis/https-www-samuel-windsor-co-uk/w3xzxkvx6o?form_factor=desktop | I7: https://pagespeed.web.dev/analysis/https-www-samuel-windsor-co-uk-collections-all/h4jutivwll?form_factor=desktop | J7: https://pagespeed.web.dev/analysis/https-www-samuel-windsor-co-uk-products-admiral-deck-shoe-brown/dw99q9f3im?form_factor=desktop
A8: https://rebelliousfashion.com | B8: 43 | C8: 76 | D8: 38 | E8: 45 | F8: 24 | G8: 63 | H8: https://pagespeed.web.dev/analysis/https-rebelliousfashion-com/9043cghita?form_factor=desktop | I8: https://pagespeed.web.dev/analysis/https-rebelliousfashion-com-collections-all/kcduob2219?form_factor=desktop | J8: https://pagespeed.web.dev/analysis/https-rebelliousfashion-com-products-black-tailored-blazer-playsuit-minzi/oni33b68tw?form_factor=desktop
A9: https://lalagebeaumont.com | B9: 43 | C9: 61 | D9: 41 | E9: 54 | F9: 33 | G9: 45 | H9: https://pagespeed.web.dev/analysis/https-lalagebeaumont-com/5cym3plnh0?form_factor=desktop | I9: https://pagespeed.web.dev/analysis/https-lalagebeaumont-com-collections-all/lle02qqn68?form_factor=desktop | J9: https://pagespeed.web.dev/analysis/https-lalagebeaumont-com-products-12mm-mother-of-pearl-stud-earrings-pink/uek7osufue?form_factor=mobile
A10: https://luxurypromise.com | B10: 56 | C10: 39 | D10: 44 | E10: 53 | F10: 38 | G10: 61 | H10: https://pagespeed.web.dev/analysis/https-luxurypromise-com/18dfht6cll?form_factor=desktop | I10: https://pagespeed.web.dev/analysis/https-luxurypromise-com-collections-all/ljowrjxjkd?form_factor=mobile | J10: https://pagespeed.web.dev/analysis/https-luxurypromise-com-collections-all-products-new-birkin-shoulder-29-poussiere-evercolor-permabrass-hardware-stamp-k-full-set-original-receipt-sycf1561/h4gmr0qgdp?form_factor=desktop
A11: https://revivalvintage.co.uk | B11: 40 | C11: 65 | D11: 37 | E11: 33 | F11: 35 | G11: 61 | H11: https://pagespeed.web.dev/analysis/https-revivalvintage-co-uk/uhfzpsepd8?form_factor=mobile | I11: https://pagespeed.web.dev/analysis/https-revivalvintage-co-uk-collections-all/3hganywbdc?form_factor=desktop | J11: https://pagespeed.web.dev/analysis/https-revivalvintage-co-uk-products-1940s-deliverance-demob-jacket-blue-herringbone/udi4r8dbgu?form_factor=mobile
A12: https://universalworks.com | B12: 14 | C12: 42 | D12: 36 | E12: 45 | F12: 20 | G12: 51 | H12: https://pagespeed.web.dev/analysis/https-universalworks-com/5a4gdo4ina?form_factor=desktop | I12: https://pagespeed.web.dev/analysis/https-universalworks-com/cixkb0tobf?form_factor=mobile | J12: https://pagespeed.web.dev/analysis/https-universalworks-com-products-dark-navy-ospina-cotton-oxford-pant/ji9ll02n9w?form_factor=desktop
A13: https://wiggykit.com | B13: 54 | C13: 63 | D13: 52 | E13: 54 | F13: 61 | G13: 78 | H13: https://pagespeed.web.dev/analysis/https-www-wiggykit-com/kphqpihbef?form_factor=desktop | I13: https://pagespeed.web.dev/analysis/https-www-wiggykit-com-collections-all/zdgtyecvcq?form_factor=desktop | J13: https://pagespeed.web.dev/analysis/https-www-wiggykit-com-products-the-keeper-dress/e3trv0anin?form_factor=desktop
A14: https://privatewhitevc.com | B14: 45 | C14: 59 | D14: 29 | E14: 44 | F14: 36 | G14: 42 | H14: https://pagespeed.web.dev/analysis/https-www-privatewhitevc-com/ggzg100el1?form_factor=mobile | I14: https://pagespeed.web.dev/analysis/https-www-privatewhitevc-com-collections-all/f6y4aben3z?form_factor=desktop | J14: https://pagespeed.web.dev/analysis/https-www-privatewhitevc-com-products-the-submariner-parka-1/ugsaofwpih?form_factor=desktop
A15: https://palaceofnowhere.co.uk | B15: 58 | C15: 25 | D15: 65 | E15: 74 | F15: 62 | G15: 64 | H15: https://pagespeed.web.dev/analysis/https-palaceofnowhere-co-uk/2ffurvjenf?form_factor=desktop | I15: https://pagespeed.web.dev/analysis/https-palaceofnowhere-co-uk-collections-all/9gxd3nwsm5?form_factor=desktop | J15: https://pagespeed.web.dev/analysis/https-palaceofnowhere-co-uk-products-2-x-vintage-60s-verrerie-d-arques-pressed-glass-candle-holders/tfkbkd7ouq?form_factor=desktop
A16: https://thrifted.com | B16: 47 | C16: 36 | D16: 33 | E16: 48 | F16: 38 | G16: 62 | H16: https://pagespeed.web.dev/analysis/https-www-thrifted-com/rdxsyvn1e8?form_factor=desktop | I16: https://pagespeed.web.dev/analysis/https-www-thrifted-com-collections-all/elr7v7grs1?form_factor=mobile | J16: https://pagespeed.web.dev/analysis/https-www-thrifted-com-products-southern-new-hampshire-university-champion-hoodie-mens-grey-small-61353-a-new/hgzufyoubd?form_factor=desktop
... A41: https://room24.co.uk | B41: 54 | C41: 58 | D41: 68 | E41: 86 | F41: 54 | G41: 64 | H41: https://pagespeed.web.dev/analysis/https-room24-co-uk/kjgoqduvg5?form_factor=mobile | I41: https://pagespeed.web.dev/analysis/https-room24-co-uk-collections-all/yq3sq57pnm?form_factor=desktop | J41: https://pagespeed.web.dev/analysis/https-room24-co-uk-products-alexa-one-piece-black-copy/8flumb29n8?form_factor=desktop
A42: https://oliviavonhalle.com | B42: 28 | C42: 35 | D42: 30 | E42: 27 | F42: 28 | G42: 63 | H42: https://pagespeed.web.dev/analysis/https-oliviavonhalle-com/c6kahtlg7s?form_factor=desktop | I42: https://pagespeed.web.dev/analysis/https-oliviavonhalle-com-collections-all/ceqpchfb99?form_factor=desktop
A43: https://luxurypromise.com | B43: 32 | C43: 37 | D43: 42 | E43: 59 | F43: 53 | G43: 65 | H43: https://pagespeed.web.dev/analysis/https-luxurypromise-com/e09nkttvxz?form_factor=desktop | I43: https://pagespeed.web.dev/analysis/https-luxurypromise-com-collections-all/i57szil3ku?form_factor=desktop | J43: https://pagespeed.web.dev/analysis/https-luxurypromise-com-collections-all-products-vintage-chanel-classic-flap-medium-chain-shoulder-bag-red-lamb-skin-gold-hardware-90308215/dzjx8pdnde?form_factor=desktop
A44: https://tocoswim.com | B44: 49 | C44: 63 | D44: 46 | E44: 37 | F44: 28 | G44: 63 | H44: https://pagespeed.web.dev/analysis/https-tocoswim-com/nl0ss802eb?form_factor=desktop | I44: https://pagespeed.web.dev/analysis/https-tocoswim-com-collections-all/fsby7qqgcv?form_factor=desktop | J44: https://pagespeed.web.dev/analysis/https-tocoswim-com-products-agni-halter-neck-triangle-bikini-top-picante-red-pink-gold-flower-print/mktiwu8n14?form_factor=desktop
A45: https://pomodoroclothing.com | B45: 47 | C45: 80 | D45: 87 | E45: 98 | F45: NA | G45: NA | H45: https://pagespeed.web.dev/analysis/https-www-pomodoroclothing-com/hu1oz4dioi?form_factor=desktop | I45: https://pagespeed.web.dev/analysis/https-www-pomodoroclothing-com-pages-collection/0juzywprgc?form_factor=desktop | J45: NA
A46: https://paradoxlondon.com | B46: 36 | C46: 44 | D46: 37 | E46: 49 | F46: 39 | G46: 40 | H46: https://pagespeed.web.dev/analysis/https-www-paradoxlondon-com/11cngkxkxs?form_factor=desktop | I46: https://pagespeed.web.dev/analysis/https-www-paradoxlondon-com-collections-all/28y21wknq6?form_factor=desktop | J46: https://pagespeed.web.dev/analysis/https-www-paradoxlondon-com-products-adorn-ivory-wide-fit-satin-block-heel-wedding-shoes/fpcltt9us5?form_factor=desktop
A47: https://maharishistore.com | B47: 58 | C47: 67 | D47: 47 | E47: 68 | F47: 46 | G47: 58 | H47: https://pagespeed.web.dev/analysis/https-www-maharishistore-com/yjapzv6t8q?form_factor=desktop | I47: https://pagespeed.web.dev/analysis/https-www-maharishistore-com-collections-all/oepv8dwkyg?form_factor=desktop | J47: https://pagespeed.web.dev/analysis/https-www-maharishistore-com-products-1113-maha-malice-monk-sling-bag-olive/etkhpaz2f0?form_factor=desktop
A48: https://stripeandstare.com | B48: 34 | C48: 60 | D48: 31 | E48: 53 | F48: 30 | G48: 44 | H48: https://pagespeed.web.dev/analysis/https-stripeandstare-com/8wycfqlzmw?form_factor=desktop | I48: https://pagespeed.web.dev/analysis/https-stripeandstare-com/3bellsl5eb?form_factor=desktop | J48: https://pagespeed.web.dev/analysis/https-stripeandstare-com-products-triangle-lace-bra-black/9n9wjlsz14?form_factor=desktop
A49: https://exude.in | B49: 96 | C49: 88 | D49: 55 | E49: 58 | F49: 83 | G49: 58 | H49: https://pagespeed.web.dev/analysis/https-www-exude-in/uwet1xr4sh?form_factor=desktop | I49: https://pagespeed.web.dev/analysis/https-www-exude-in-collections-all/8azg1wmgyo?form_factor=desktop | J49: https://pagespeed.web.dev/analysis/https-www-exude-in-products-black-ribbed-peplum-co-ord-set-choker-neck-top-wide-leg-pants/jt7m1y98mf?form_factor=desktop
A50: https://mariechantal.com | B50: 40 | C50: 40 | D50: 29 | E50: 42 | F50: 29 | G50: 39 | H50: https://pagespeed.web.dev/analysis/https-www-mariechantal-com/5dxtyht406?form_factor=desktop | I50: https://pagespeed.web.dev/analysis/https-www-mariechantal-com-collections-all/29uhizocdu?form_factor=desktop | J50: https://pagespeed.web.dev/analysis/https-www-mariechantal-com-products-camille-tennis-baby-jumper-pink/ly8xgdldf1?form_factor=desktop
A51: https://peachyden.co.uk | B51: 34 | C51: 78 | D51: 53 | E51: 53 | F51: 40 | G51: 34 | H51: https://pagespeed.web.dev/analysis/https-www-peachyden-co-uk/srrhu3eni7?form_factor=desktop | I51: https://pagespeed.web.dev/analysis/https-www-peachyden-co-uk-collections-all-products/w12lk7l93l?form_factor=desktop | J51: https://pagespeed.web.dev/analysis/https-www-peachyden-co-uk-collections-all-products-products-the-cindy-halter-top-fir-tree/qtdkuegq1b?form_factor=mobile
A52: https://theunseenlabel.com | B52: 49 | C52: 77 | D52: 57 | E52: 62 | F52: 54 | G52: 76 | H52: https://pagespeed.web.dev/analysis/https-theunseenlabel-com/foabbytnts?form_factor=desktop | I52: https://pagespeed.web.dev/analysis/https-theunseenlabel-com-collections-all/bm3hcdx7is?form_factor=desktop | J52: https://pagespeed.web.dev/analysis/https-theunseenlabel-com-collections-all-products-the-ease-bra-1/v6ji46gwsm?form_factor=desktop
A53: https://yourmusa.com | B53: 54 | C53: 75 | D53: 52 | E53: 45 | F53: 57 | G53: 33 | H53: https://pagespeed.web.dev/analysis/https-yourmusa-com/0gyppgvtu3?form_factor=desktop | I53: https://pagespeed.web.dev/analysis/https-yourmusa-com-collections-all/ck89hul5k7?form_factor=desktop | J53: https://pagespeed.web.dev/analysis/https-yourmusa-com-products-antique-corset-green-tapestry/ol71q2kir2?form_factor=desktop
A54: https://lapochette.co | B54: 48 | C54: 71 | D54: 46 | E54: 88 | F54: 40 | G54: 57 | H54: https://pagespeed.web.dev/analysis/https-lapochette-co/6duwv58x4a?form_factor=desktop | I54: https://pagespeed.web.dev/analysis/https-lapochette-co-collections-all/1psouj60q7?form_factor=desktop | J54: https://pagespeed.web.dev/analysis/https-lapochette-co-products-anywhere-everywhere-box-charcoal-ink/h9eo2s4hxd?form_factor=desktop
A55: https://labrumlondon.com | B55: 59 | C55: 92 | D55: 59 | E55: 57 | F55: 41 | G55: 72 | H55: https://pagespeed.web.dev/analysis/https-labrumlondon-com/p3heatc48p?form_factor=desktop | I55: https://pagespeed.web.dev/analysis/https-labrumlondon-com-collections-all/o2txe18qra?form_factor=desktop | J55: https://pagespeed.web.dev/analysis/https-labrumlondon-com-products-labrum-x-adidas-adizero-adios-pro-4/dic5wutz2v?form_factor=desktop
A56: https://lachesis.london | B56: 57 | C56: 74 | D56: 44 | E56: 80 | F56: 48 | G56: 64 | H56: https://pagespeed.web.dev/analysis/https-lachesis-london/zd4obaxn95?form_factor=desktop | I56: https://pagespeed.web.dev/analysis/https-lachesis-london-collections-all/u5if97xtwh?form_factor=desktop | J56: https://pagespeed.web.dev/analysis/https-lachesis-london-products-bottletop-kibe-belt-silver-black/cn4fw8poyb?form_factor=desktop
A57: https://lacyloulondon.com | B57: 54 | C57: 77 | D57: 38 | E57: 50 | F57: 44 | G57: 47 | H57: https://pagespeed.web.dev/analysis/https-lacyloulondon-com/fi2baw6rhx?form_factor=desktop | I57: https://pagespeed.web.dev/analysis/https-www-lacyloulondon-com-collections-all/ltij72lvfg?form_factor=desktop | J57: https://pagespeed.web.dev/analysis/https-www-lacyloulondon-com-products-adorable-bow/bex5okvwhs?form_factor=desktop
... A82: https://lifesbetteroutdoors.co.uk | B82: 49 | C82: 71 | D82: 63 | E82: 78 | F82: 49 | G82: 68 | H82: https://pagespeed.web.dev/analysis/https-lifesbetteroutdoors-co-uk/f8ersapn2b?form_factor=desktop | I82: https://pagespeed.web.dev/analysis/https-lifesbetteroutdoors-co-uk-collections-all/mx5bmm1126?form_factor=desktop | J82: https://pagespeed.web.dev/analysis/https-lifesbetteroutdoors-co-uk-products-abisko-midsummer-jacket/8pxbojb1lp?form_factor=desktop
A83: https://lillebei.com | B83: Store does not exist
A84: https://lilliesstudios.com | B84: 63 | C84: 92 | D84: 66 | E84: 92 | F84: 71 | G84: 94 | H84: https://pagespeed.web.dev/analysis/https-lilliesstudios-com/e4h0vc7q2n?form_factor=desktop | I84: https://pagespeed.web.dev/analysis/https-lilliesstudios-com-collections-all/9hgryh46ea?form_factor=desktop | J84: https://pagespeed.web.dev/analysis/https-lilliesstudios-com-products-1960-s-blue-check-flannel-shirt/h2gmi21vtv?form_factor=desktop
A85: https://lilyandmeclothing.com | B85: 32 | C85: 56 | D85: 50 | E85: 67 | F85: 42 | G85: 57 | H85: https://pagespeed.web.dev/analysis/https-www-lilyandmeclothing-com/09lqwzivp5?form_factor=desktop | I85: https://pagespeed.web.dev/analysis/https-www-lilyandmeclothing-com-collections-all/81eni48akq?form_factor=desktop | J85: https://pagespeed.web.dev/analysis/https-www-lilyandmeclothing-com-products-3-4-length-cropped-leggings-navy/i2lwr3q80i?form_factor=desktop
A86: https://lilyarkwright.com | B86: 38 | C86: 70 | D86: 41 | E86: 48 | F86: 38 | G86: 56 | H86: https://pagespeed.web.dev/analysis/https-lilyarkwright-com/v7tipnewf6?form_factor=desktop | I86: https://pagespeed.web.dev/analysis/https-lilyarkwright-com-collections-all/h5wd5h1b2u?form_factor=desktop | J86: https://pagespeed.web.dev/analysis/https-lilyarkwright-com-products-womens-plain-wedding-band-bevelled-edge-profile-18k-rose-gold/1fuev79m5z?form_factor=desktop
A87: https://lilyrou.com | B87: 76 | C87: 96 | D87: 82 | E87: 95 | F87: 84 | G87: 80 | H87: https://pagespeed.web.dev/analysis/https-lilyrou-com/xp0vs5usns?form_factor=desktop | I87: https://pagespeed.web.dev/analysis/https-lilyrou-com-collections-all/bzetkq61zq?form_factor=desktop | J87: https://pagespeed.web.dev/analysis/https-lilyrou-com-products-90s-slip-dress-coral/f56hqquua8?form_factor=desktop
A88: https://lindseybrown.com | B88: 70 | C88: 90 | D88: 77 | E88: 93 | F88: 57 | G88: 63 | H88: https://pagespeed.web.dev/analysis/https-www-lindseybrown-com/tnbjidneds?form_factor=desktop | I88: https://pagespeed.web.dev/analysis/https-www-lindseybrown-com-collections-all/39c7w1wfkt?form_factor=desktop | J88: https://pagespeed.web.dev/analysis/https-www-lindseybrown-com-products-animal-print-silk-designer-maxi-dress/q08kezq5gu?form_factor=desktop
...
